{
 "cells": [
  {
   "cell_type": "code",
   "execution_count": 1,
   "metadata": {},
   "outputs": [
    {
     "name": "stdout",
     "output_type": "stream",
     "text": [
      "/tf/notebooks/notebooks\n",
      "Requirement already satisfied: pandas in /usr/local/lib/python3.11/dist-packages (2.1.3)\n",
      "Requirement already satisfied: numpy<2,>=1.23.2 in /usr/local/lib/python3.11/dist-packages (from pandas) (1.26.0)\n",
      "Requirement already satisfied: python-dateutil>=2.8.2 in /usr/local/lib/python3.11/dist-packages (from pandas) (2.8.2)\n",
      "Requirement already satisfied: pytz>=2020.1 in /usr/local/lib/python3.11/dist-packages (from pandas) (2023.3.post1)\n",
      "Requirement already satisfied: tzdata>=2022.1 in /usr/local/lib/python3.11/dist-packages (from pandas) (2023.3)\n",
      "Requirement already satisfied: six>=1.5 in /usr/lib/python3/dist-packages (from python-dateutil>=2.8.2->pandas) (1.16.0)\n",
      "\u001b[33mWARNING: Running pip as the 'root' user can result in broken permissions and conflicting behaviour with the system package manager. It is recommended to use a virtual environment instead: https://pip.pypa.io/warnings/venv\u001b[0m\u001b[33m\n",
      "\u001b[0m\n",
      "\u001b[1m[\u001b[0m\u001b[34;49mnotice\u001b[0m\u001b[1;39;49m]\u001b[0m\u001b[39;49m A new release of pip is available: \u001b[0m\u001b[31;49m23.2.1\u001b[0m\u001b[39;49m -> \u001b[0m\u001b[32;49m23.3.1\u001b[0m\n",
      "\u001b[1m[\u001b[0m\u001b[34;49mnotice\u001b[0m\u001b[1;39;49m]\u001b[0m\u001b[39;49m To update, run: \u001b[0m\u001b[32;49mpython3 -m pip install --upgrade pip\u001b[0m\n",
      "Note: you may need to restart the kernel to use updated packages.\n"
     ]
    }
   ],
   "source": [
    "%cd /tf/notebooks/notebooks\n",
    "%pip install pandas"
   ]
  },
  {
   "cell_type": "code",
   "execution_count": 2,
   "metadata": {},
   "outputs": [
    {
     "name": "stderr",
     "output_type": "stream",
     "text": [
      "2023-11-16 10:13:46.766803: E tensorflow/compiler/xla/stream_executor/cuda/cuda_dnn.cc:9342] Unable to register cuDNN factory: Attempting to register factory for plugin cuDNN when one has already been registered\n",
      "2023-11-16 10:13:46.766845: E tensorflow/compiler/xla/stream_executor/cuda/cuda_fft.cc:609] Unable to register cuFFT factory: Attempting to register factory for plugin cuFFT when one has already been registered\n",
      "2023-11-16 10:13:46.766862: E tensorflow/compiler/xla/stream_executor/cuda/cuda_blas.cc:1518] Unable to register cuBLAS factory: Attempting to register factory for plugin cuBLAS when one has already been registered\n",
      "2023-11-16 10:13:46.771736: I tensorflow/core/platform/cpu_feature_guard.cc:182] This TensorFlow binary is optimized to use available CPU instructions in performance-critical operations.\n",
      "To enable the following instructions: AVX2 FMA, in other operations, rebuild TensorFlow with the appropriate compiler flags.\n",
      "2023-11-16 10:13:48.258919: I tensorflow/compiler/xla/stream_executor/cuda/cuda_gpu_executor.cc:880] could not open file to read NUMA node: /sys/bus/pci/devices/0000:01:00.0/numa_node\n",
      "Your kernel may have been built without NUMA support.\n",
      "2023-11-16 10:13:48.263046: I tensorflow/compiler/xla/stream_executor/cuda/cuda_gpu_executor.cc:880] could not open file to read NUMA node: /sys/bus/pci/devices/0000:01:00.0/numa_node\n",
      "Your kernel may have been built without NUMA support.\n",
      "2023-11-16 10:13:48.263072: I tensorflow/compiler/xla/stream_executor/cuda/cuda_gpu_executor.cc:880] could not open file to read NUMA node: /sys/bus/pci/devices/0000:01:00.0/numa_node\n",
      "Your kernel may have been built without NUMA support.\n",
      "2023-11-16 10:13:48.264564: I tensorflow/compiler/xla/stream_executor/cuda/cuda_gpu_executor.cc:880] could not open file to read NUMA node: /sys/bus/pci/devices/0000:01:00.0/numa_node\n",
      "Your kernel may have been built without NUMA support.\n",
      "2023-11-16 10:13:48.264583: I tensorflow/compiler/xla/stream_executor/cuda/cuda_gpu_executor.cc:880] could not open file to read NUMA node: /sys/bus/pci/devices/0000:01:00.0/numa_node\n",
      "Your kernel may have been built without NUMA support.\n",
      "2023-11-16 10:13:48.264591: I tensorflow/compiler/xla/stream_executor/cuda/cuda_gpu_executor.cc:880] could not open file to read NUMA node: /sys/bus/pci/devices/0000:01:00.0/numa_node\n",
      "Your kernel may have been built without NUMA support.\n",
      "2023-11-16 10:13:48.438112: I tensorflow/compiler/xla/stream_executor/cuda/cuda_gpu_executor.cc:880] could not open file to read NUMA node: /sys/bus/pci/devices/0000:01:00.0/numa_node\n",
      "Your kernel may have been built without NUMA support.\n",
      "2023-11-16 10:13:48.438164: I tensorflow/compiler/xla/stream_executor/cuda/cuda_gpu_executor.cc:880] could not open file to read NUMA node: /sys/bus/pci/devices/0000:01:00.0/numa_node\n",
      "Your kernel may have been built without NUMA support.\n",
      "2023-11-16 10:13:48.438172: I tensorflow/core/common_runtime/gpu/gpu_device.cc:1977] Could not identify NUMA node of platform GPU id 0, defaulting to 0.  Your kernel may not have been built with NUMA support.\n",
      "2023-11-16 10:13:48.438204: I tensorflow/compiler/xla/stream_executor/cuda/cuda_gpu_executor.cc:880] could not open file to read NUMA node: /sys/bus/pci/devices/0000:01:00.0/numa_node\n",
      "Your kernel may have been built without NUMA support.\n",
      "2023-11-16 10:13:48.438232: I tensorflow/core/common_runtime/gpu/gpu_device.cc:1886] Created device /job:localhost/replica:0/task:0/device:GPU:0 with 5578 MB memory:  -> device: 0, name: NVIDIA GeForce RTX 4060 Laptop GPU, pci bus id: 0000:01:00.0, compute capability: 8.9\n"
     ]
    }
   ],
   "source": [
    "from tensorflow.keras.models import load_model\n",
    "\n",
    "# load model\n",
    "model_path = 'models/best_model_0899.h5'\n",
    "model = load_model(model_path)"
   ]
  },
  {
   "cell_type": "code",
   "execution_count": 7,
   "metadata": {},
   "outputs": [],
   "source": [
    "# Accuracy\n",
    "import pandas as pd\n",
    "\n",
    "version = 1\n",
    "X_data_path = 'clean_data/v{version}_X_test.csv'.format(version=version)\n",
    "Y_data_path = 'clean_data/v{version}_Y_test.csv'.format(version=version)\n",
    "X = pd.read_csv(X_data_path)\n",
    "Y = pd.read_csv(Y_data_path)"
   ]
  },
  {
   "cell_type": "code",
   "execution_count": 10,
   "metadata": {},
   "outputs": [
    {
     "ename": "ValueError",
     "evalue": "in user code:\n\n    File \"/usr/local/lib/python3.11/dist-packages/keras/src/engine/training.py\", line 2042, in test_function  *\n        return step_function(self, iterator)\n    File \"/usr/local/lib/python3.11/dist-packages/keras/src/engine/training.py\", line 2025, in step_function  **\n        outputs = model.distribute_strategy.run(run_step, args=(data,))\n    File \"/usr/local/lib/python3.11/dist-packages/keras/src/engine/training.py\", line 2013, in run_step  **\n        outputs = model.test_step(data)\n    File \"/usr/local/lib/python3.11/dist-packages/keras/src/engine/training.py\", line 1895, in test_step\n        self.compute_loss(x, y, y_pred, sample_weight)\n    File \"/usr/local/lib/python3.11/dist-packages/keras/src/engine/training.py\", line 1185, in compute_loss\n        return self.compiled_loss(\n    File \"/usr/local/lib/python3.11/dist-packages/keras/src/engine/compile_utils.py\", line 277, in __call__\n        loss_value = loss_obj(y_t, y_p, sample_weight=sw)\n    File \"/usr/local/lib/python3.11/dist-packages/keras/src/losses.py\", line 143, in __call__\n        losses = call_fn(y_true, y_pred)\n    File \"/usr/local/lib/python3.11/dist-packages/keras/src/losses.py\", line 270, in call  **\n        return ag_fn(y_true, y_pred, **self._fn_kwargs)\n    File \"/usr/local/lib/python3.11/dist-packages/keras/src/losses.py\", line 2221, in categorical_crossentropy\n        return backend.categorical_crossentropy(\n    File \"/usr/local/lib/python3.11/dist-packages/keras/src/backend.py\", line 5575, in categorical_crossentropy\n        target.shape.assert_is_compatible_with(output.shape)\n\n    ValueError: Shapes (None, 1) and (None, 10) are incompatible\n",
     "output_type": "error",
     "traceback": [
      "\u001b[0;31m---------------------------------------------------------------------------\u001b[0m",
      "\u001b[0;31mValueError\u001b[0m                                Traceback (most recent call last)",
      "\u001b[1;32mc:\\Users\\fcola\\Documents\\COURS\\opendata\\music_genre_classification\\notebooks\\accuracy.ipynb Cell 4\u001b[0m line \u001b[0;36m2\n\u001b[1;32m      <a href='vscode-notebook-cell:/c%3A/Users/fcola/Documents/COURS/opendata/music_genre_classification/notebooks/accuracy.ipynb#W2sZmlsZQ%3D%3D?line=0'>1</a>\u001b[0m \u001b[39m# PrÃ©cision\u001b[39;00m\n\u001b[0;32m----> <a href='vscode-notebook-cell:/c%3A/Users/fcola/Documents/COURS/opendata/music_genre_classification/notebooks/accuracy.ipynb#W2sZmlsZQ%3D%3D?line=1'>2</a>\u001b[0m score \u001b[39m=\u001b[39m model\u001b[39m.\u001b[39;49mevaluate(X, Y, verbose\u001b[39m=\u001b[39;49m\u001b[39m1\u001b[39;49m)\n\u001b[1;32m      <a href='vscode-notebook-cell:/c%3A/Users/fcola/Documents/COURS/opendata/music_genre_classification/notebooks/accuracy.ipynb#W2sZmlsZQ%3D%3D?line=2'>3</a>\u001b[0m \u001b[39mprint\u001b[39m(\u001b[39m'\u001b[39m\u001b[39mTest loss:\u001b[39m\u001b[39m'\u001b[39m, score[\u001b[39m0\u001b[39m])\n\u001b[1;32m      <a href='vscode-notebook-cell:/c%3A/Users/fcola/Documents/COURS/opendata/music_genre_classification/notebooks/accuracy.ipynb#W2sZmlsZQ%3D%3D?line=3'>4</a>\u001b[0m \u001b[39mprint\u001b[39m(\u001b[39m'\u001b[39m\u001b[39mTest accuracy:\u001b[39m\u001b[39m'\u001b[39m, score[\u001b[39m1\u001b[39m])\n",
      "File \u001b[0;32m/usr/local/lib/python3.11/dist-packages/keras/src/utils/traceback_utils.py:70\u001b[0m, in \u001b[0;36mfilter_traceback.<locals>.error_handler\u001b[0;34m(*args, **kwargs)\u001b[0m\n\u001b[1;32m     67\u001b[0m     filtered_tb \u001b[39m=\u001b[39m _process_traceback_frames(e\u001b[39m.\u001b[39m__traceback__)\n\u001b[1;32m     68\u001b[0m     \u001b[39m# To get the full stack trace, call:\u001b[39;00m\n\u001b[1;32m     69\u001b[0m     \u001b[39m# `tf.debugging.disable_traceback_filtering()`\u001b[39;00m\n\u001b[0;32m---> 70\u001b[0m     \u001b[39mraise\u001b[39;00m e\u001b[39m.\u001b[39mwith_traceback(filtered_tb) \u001b[39mfrom\u001b[39;00m \u001b[39mNone\u001b[39;00m\n\u001b[1;32m     71\u001b[0m \u001b[39mfinally\u001b[39;00m:\n\u001b[1;32m     72\u001b[0m     \u001b[39mdel\u001b[39;00m filtered_tb\n",
      "File \u001b[0;32m/tmp/__autograph_generated_filehnvo57jd.py:15\u001b[0m, in \u001b[0;36mouter_factory.<locals>.inner_factory.<locals>.tf__test_function\u001b[0;34m(iterator)\u001b[0m\n\u001b[1;32m     13\u001b[0m \u001b[39mtry\u001b[39;00m:\n\u001b[1;32m     14\u001b[0m     do_return \u001b[39m=\u001b[39m \u001b[39mTrue\u001b[39;00m\n\u001b[0;32m---> 15\u001b[0m     retval_ \u001b[39m=\u001b[39m ag__\u001b[39m.\u001b[39mconverted_call(ag__\u001b[39m.\u001b[39mld(step_function), (ag__\u001b[39m.\u001b[39mld(\u001b[39mself\u001b[39m), ag__\u001b[39m.\u001b[39mld(iterator)), \u001b[39mNone\u001b[39;00m, fscope)\n\u001b[1;32m     16\u001b[0m \u001b[39mexcept\u001b[39;00m:\n\u001b[1;32m     17\u001b[0m     do_return \u001b[39m=\u001b[39m \u001b[39mFalse\u001b[39;00m\n",
      "\u001b[0;31mValueError\u001b[0m: in user code:\n\n    File \"/usr/local/lib/python3.11/dist-packages/keras/src/engine/training.py\", line 2042, in test_function  *\n        return step_function(self, iterator)\n    File \"/usr/local/lib/python3.11/dist-packages/keras/src/engine/training.py\", line 2025, in step_function  **\n        outputs = model.distribute_strategy.run(run_step, args=(data,))\n    File \"/usr/local/lib/python3.11/dist-packages/keras/src/engine/training.py\", line 2013, in run_step  **\n        outputs = model.test_step(data)\n    File \"/usr/local/lib/python3.11/dist-packages/keras/src/engine/training.py\", line 1895, in test_step\n        self.compute_loss(x, y, y_pred, sample_weight)\n    File \"/usr/local/lib/python3.11/dist-packages/keras/src/engine/training.py\", line 1185, in compute_loss\n        return self.compiled_loss(\n    File \"/usr/local/lib/python3.11/dist-packages/keras/src/engine/compile_utils.py\", line 277, in __call__\n        loss_value = loss_obj(y_t, y_p, sample_weight=sw)\n    File \"/usr/local/lib/python3.11/dist-packages/keras/src/losses.py\", line 143, in __call__\n        losses = call_fn(y_true, y_pred)\n    File \"/usr/local/lib/python3.11/dist-packages/keras/src/losses.py\", line 270, in call  **\n        return ag_fn(y_true, y_pred, **self._fn_kwargs)\n    File \"/usr/local/lib/python3.11/dist-packages/keras/src/losses.py\", line 2221, in categorical_crossentropy\n        return backend.categorical_crossentropy(\n    File \"/usr/local/lib/python3.11/dist-packages/keras/src/backend.py\", line 5575, in categorical_crossentropy\n        target.shape.assert_is_compatible_with(output.shape)\n\n    ValueError: Shapes (None, 1) and (None, 10) are incompatible\n"
     ]
    }
   ],
   "source": [
    "# PrÃ©cision\n",
    "score = model.evaluate(X, Y, verbose=1)\n",
    "print('Test loss:', score[0])\n",
    "print('Test accuracy:', score[1])"
   ]
  }
 ],
 "metadata": {
  "kernelspec": {
   "display_name": "Python 3 (ipykernel)",
   "language": "python",
   "name": "python3"
  }
 },
 "nbformat": 4,
 "nbformat_minor": 2
}
